Workbook
Name AsOf: Inputs!$B$3
Name ExcessDays: Inputs!$B$1
Name MinVolume: Inputs!$B$2

Sheet Demand pivot per SKU
A3: Units by product and month | B3: Month
B4: 2015 | N4: 2016 | Z4: 2017 | AI4: Grand Total
A5: Product ID | B5: Jan | C5: Feb | D5: Mar | E5: Apr | F5: May | G5: Jun | H5: Jul | I5: Aug | J5: Sep | K5: Oct | L5: Nov | M5: Dec | N5: Jan | O5: Feb | P5: Mar | Q5: Apr | R5: May | S5: Jun | T5: Jul | U5: Aug | V5: Sep | W5: Oct | X5: Nov | Y5: Dec | Z5: Jan | AA5: Feb | AB5: Mar | AC5: Apr | AD5: May | AE5: Jun | AF5: Jul | AG5: Aug | AH5: Sep
A6: 19 | B6: 0 | C6: 0 | D6: 0 | E6: 0 | F6: 0 | G6: 0 | H6: 0 | I6: 0 | J6: 0 | K6: 0 | L6: 0 | M6: 0 | N6: 0 | O6: 0 | P6: 0 | Q6: 0 | R6: 0 | S6: 0 | T6: 0 | U6: 0 | V6: 0 | W6: 0 | X6: 0 | Y6: 0 | Z6: 0 | AA6: 0 | AB6: 0 | AC6: 2 | AD6: 13 | AE6: 13 | AF6: 14 | AG6: 17 | AH6: 4 | AI6: 63
A7: 24 | B7: 0 | C7: 0 | D7: 0 | E7: 0 | F7: 0 | G7: 0 | H7: 0 | I7: 0 | J7: 0 | K7: 0 | L7: 0 | M7: 0 | N7: 0 | O7: 0 | P7: 0 | Q7: 0 | R7: 0 | S7: 0 | T7: 0 | U7: 0 | V7: 0 | W7: 0 | X7: 0 | Y7: 0 | Z7: 0 | AA7: 0 | AB7: 0 | AC7: 12 | AD7: 70 | AE7: 52 | AF7: 45 | AG7: 42 | AH7: 9 | AI7: 230
A8: 35 | B8: 0 | C8: 0 | D8: 0 | E8: 0 | F8: 0 | G8: 0 | H8: 0 | I8: 0 | J8: 0 | K8: 0 | L8: 0 | M8: 0 | N8: 0 | O8: 0 | P8: 0 | Q8: 0 | R8: 0 | S8: 0 | T8: 0 | U8: 0 | V8: 0 | W8: 0 | X8: 0 | Y8: 0 | Z8: 0 | AA8: 0 | AB8: 0 | AC8: 4 | AD8: 15 | AE8: 11 | AF8: 14 | AG8: 13 | AH8: 5 | AI8: 62
A9: 37 | B9: 18 | C9: 20 | D9: 13 | E9: 29 | F9: 25 | G9: 11 | H9: 30 | I9: 20 | J9: 31 | K9: 8 | L9: 44 | M9: 39 | N9: 19 | O9: 32 | P9: 24 | Q9: 38 | R9: 24 | S9: 19 | T9: 52 | U9: 20 | V9: 15 | W9: 27 | X9: 34 | Y9: 24 | Z9: 34 | AA9: 28 | AB9: 48 | AC9: 14 | AD9: 0 | AE9: 0 | AF9: 0 | AG9: 0 | AH9: 0 | AI9: 740
A10: 44 | B10: 50 | C10: 23 | D10: 52 | E10: 34 | F10: 30 | G10: 33 | H10: 40 | I10: 21 | J10: 39 | K10: 31 | L10: 8 | M10: 37 | N10: 19 | O10: 36 | P10: 35 | Q10: 40 | R10: 45 | S10: 11 | T10: 51 | U10: 20 | V10: 45 | W10: 33 | X10: 25 | Y10: 35 | Z10: 30 | AA10: 17 | AB10: 36 | AC10: 36 | AD10: 0 | AE10: 0 | AF10: 0 | AG10: 0 | AH10: 0 | AI10: 912
A11: 58 | B11: 0 | C11: 0 | D11: 0 | E11: 0 | F11: 0 | G11: 0 | H11: 0 | I11: 0 | J11: 0 | K11: 0 | L11: 0 | M11: 0 | N11: 0 | O11: 0 | P11: 0 | Q11: 0 | R11: 0 | S11: 0 | T11: 0 | U11: 0 | V11: 0 | W11: 0 | X11: 0 | Y11: 0 | Z11: 0 | AA11: 0 | AB11: 0 | AC11: 0 | AD11: 0 | AE11: 0 | AF11: 0 | AG11: 0 | AH11: 28 | AI11: 28
A12: 60 | B12: 0 | C12: 0 | D12: 0 | E12: 0 | F12: 0 | G12: 0 | H12: 0 | I12: 0 | J12: 0 | K12: 0 | L12: 0 | M12: 0 | N12: 0 | O12: 0 | P12: 0 | Q12: 0 | R12: 0 | S12: 0 | T12: 0 | U12: 0 | V12: 0 | W12: 0 | X12: 0 | Y12: 0 | Z12: 0 | AA12: 0 | AB12: 0 | AC12: 0 | AD12: 0 | AE12: 0 | AF12: 0 | AG12: 0 | AH12: 2 | AI12: 2
A13: 61 | B13: 0 | C13: 0 | D13: 0 | E13: 0 | F13: 0 | G13: 0 | H13: 0 | I13: 0 | J13: 0 | K13: 0 | L13: 0 | M13: 0 | N13: 0 | O13: 0 | P13: 0 | Q13: 0 | R13: 0 | S13: 0 | T13: 0 | U13: 0 | V13: 0 | W13: 0 | X13: 0 | Y13: 0 | Z13: 0 | AA13: 0 | AB13: 0 | AC13: 0 | AD13: 0 | AE13: 0 | AF13: 0 | AG13: 0 | AH13: 26 | AI13: 26
A14: 78 | B14: 0 | C14: 0 | D14: 0 | E14: 0 | F14: 0 | G14: 0 | H14: 0 | I14: 0 | J14: 0 | K14: 0 | L14: 0 | M14: 0 | N14: 0 | O14: 0 | P14: 0 | Q14: 0 | R14: 0 | S14: 0 | T14: 0 | U14: 0 | V14: 0 | W14: 0 | X14: 0 | Y14: 0 | Z14: 0 | AA14: 0 | AB14: 0 | AC14: 10 | AD14: 42 | AE14: 43 | AF14: 37 | AG14: 33 | AH14: 16 | AI14: 181
A15: 93 | B15: 31 | C15: 20 | D15: 28 | E15: 24 | F15: 48 | G15: 19 | H15: 36 | I15: 31 | J15: 19 | K15: 29 | L15: 14 | M15: 29 | N15: 18 | O15: 26 | P15: 31 | Q15: 32 | R15: 21 | S15: 34 | T15: 25 | U15: 16 | V15: 23 | W15: 23 | X15: 38 | Y15: 48 | Z15: 44 | AA15: 41 | AB15: 35 | AC15: 14 | AD15: 0 | AE15: 0 | AF15: 0 | AG15: 0 | AH15: 0 | AI15: 797
A16: 116 | B16: 44 | C16: 28 | D16: 43 | E16: 24 | F16: 20 | G16: 26 | H16: 47 | I16: 39 | J16: 38 | K16: 26 | L16: 35 | M16: 36 | N16: 26 | O16: 21 | P16: 37 | Q16: 63 | R16: 30 | S16: 35 | T16: 40 | U16: 27 | V16: 40 | W16: 21 | X16: 29 | Y16: 42 | Z16: 41 | AA16: 43 | AB16: 30 | AC16: 23 | AD16: 0 | AE16: 0 | AF16: 0 | AG16: 0 | AH16: 0 | AI16: 954
A17: 127 | B17: 0 | C17: 0 | D17: 0 | E17: 0 | F17: 0 | G17: 0 | H17: 0 | I17: 0 | J17: 0 | K17: 0 | L17: 0 | M17: 0 | N17: 0 | O17: 0 | P17: 0 | Q17: 0 | R17: 0 | S17: 0 | T17: 0 | U17: 0 | V17: 0 | W17: 0 | X17: 0 | Y17: 0 | Z17: 0 | AA17: 0 | AB17: 0 | AC17: 0 | AD17: 0 | AE17: 0 | AF17: 0 | AG17: 0 | AH17: 25 | AI17: 25
... A105: 1073 | B105: 453 | C105: 407 | D105: 449 | E105: 468 | F105: 472 | G105: 444 | H105: 458 | I105: 461 | J105: 410 | K105: 467 | L105: 443 | M105: 478 | N105: 438 | O105: 412 | P105: 434 | Q105: 415 | R105: 495 | S105: 393 | T105: 487 | U105: 449 | V105: 456 | W105: 475 | X105: 459 | Y105: 422 | Z105: 419 | AA105: 427 | AB105: 478 | AC105: 461 | AD105: 458 | AE105: 435 | AF105: 448 | AG105: 498 | AH105: 446 | AI105: 14815
A106: Grand Total | B106: 11350 | C106: 9912 | D106: 11526 | E106: 10790 | F106: 11314 | G106: 10750 | H106: 11405 | I106: 11089 | J106: 10890 | K106: 11181 | L106: 11011 | M106: 11277 | N106: 11184 | O106: 10283 | P106: 10925 | Q106: 10722 | R106: 11067 | S106: 10564 | T106: 10975 | U106: 11337 | V106: 10882 | W106: 11506 | X106: 10951 | Y106: 11271 | Z106: 11175 | AA106: 10574 | AB106: 11240 | AC106: 10716 | AD106: 10451 | AE106: 9733 | AF106: 10493 | AG106: 10685 | AH106: 9934 | AI106: 359163

Sheet ABC Analysis
A1: Source pivots for the ABC classification - sorted by revenue (left) and by units (right). Final classes are in ABC Analysis combined.
A3: Product ID | B3: Revenue ($) | C3: Cumulative revenue ($) | D3: Cumulative % (revenue) | G3: Product ID | H3: Units | I3: Cumulative units | J3: Cumulative % (units)
A4: 1004 | B4: 6631668.6 | C4: 6631668.6 | D4: 0.20225747 | G4: 365 | H4: 70455 | I4: 70455 | J4: 0.19616442
A5: 365 | B5: 4226595.6 | C5: 10858264 | D5: 0.33116327 | G5: 502 | H5: 60154 | I5: 130609 | J5: 0.36364826
A6: 957 | B6: 3942337.3 | C6: 14800601 | D6: 0.45139956 | G6: 1014 | H6: 55265 | I6: 185874 | J6: 0.5175199
A7: 191 | B7: 3501149.8 | C7: 18301751 | D7: 0.55818018 | G7: 191 | H7: 35015 | I7: 220889 | J7: 0.61501045
A8: 502 | B8: 3007700 | C8: 21309451 | D8: 0.64991122 | G8: 627 | H8: 30355 | I8: 251244 | J8: 0.6995264
A9: 1073 | B9: 2962851.9 | C9: 24272303 | D9: 0.74027444 | G9: 403 | H9: 21233 | I9: 272477 | J9: 0.7586444
A10: 1014 | B10: 2762144.7 | C10: 27034448 | D10: 0.82451635 | G10: 1004 | H10: 16580 | I10: 289057 | J10: 0.80480729
A11: 403 | B11: 2760077.8 | C11: 29794526 | D11: 0.90869522 | G11: 1073 | H11: 14815 | I11: 303872 | J11: 0.84605597
A12: 627 | B12: 1213896.5 | C12: 31008422 | D12: 0.94571752 | G12: 957 | H12: 13142 | I12: 317014 | J12: 0.8826466
A13: 565 | B13: 63490 | C13: 31071912 | D13: 0.94765388 | G13: 977 | H13: 965 | I13: 317979 | J13: 0.8853334
A14: 728 | B14: 58695 | C14: 31130607 | D14: 0.94944401 | G14: 116 | H14: 954 | I14: 318933 | J14: 0.88798958
A15: 44 | B15: 54710.882 | C15: 31185318 | D15: 0.95111262 | G15: 885 | H15: 920 | I15: 319853 | J15: 0.89055109
... A103: 60 | B103: 1999.98 | C103: 32788250 | D103: 1 | G103: 60 | H103: 2 | I103: 359163 | J103: 1
A104: Grand Total | B104: 32788250 | G104: Grand Total | H104: 359163

Sheet ABC Analysis combined
A1: Product ID | B1: Sales | C1: Rev cum % | D1: Rev class | E1: Units | F1: Units cum % | G1: Units class | H1: Tier gap | K1: Rev class | L1: Products | M1: % of product | N1: Revenue | O1: % of revenue | P1: Units (of these products) | Q1: % of units
A2: 1004 | B2: 6631668.6 | C2: 0.20225747 | D2: A | E2: =_xlfn.XLOOKUP(A2,'ABC Analysis'!$G:$G,'ABC Analysis'!H:H,,0) -> 16580 | F2: =_xlfn.XLOOKUP(A2,'ABC Analysis'!G:G,'ABC Analysis'!J:J,,0) -> 0.80480729 | G2: =_xlfn.LET(_xlpm.prev,Table3[[#This Row],[Units cum %]]-Table3[[#This Row],[Units]]/SUM(Table3[Units]),IF(_xlpm.prev<0.88,"A",IF(_xlpm.prev<0.987,"B","C"))) -> A | H2: =ABS(CODE(Table3[[#This Row],[Rev class]])-CODE(Table3[[#This Row],[Units class]])) -> 0 | K2: A | L2: =COUNTIF(D:D,"A") -> 9 | M2: =L2/100 -> 0.09 | N2: =SUMIF(Table3[Rev class],"A",Table3[Sales]) -> 31008422 | O2: =N2/(SUM(Table3[Sales])) -> 0.94571752 | P2: =SUMIF(Table3[Rev class],"A",Table3[Units]) -> 317014 | Q2: =Table5[[#This Row],[Units (of these products)]]/Table5[[#Totals],[Units (of these products)]] -> 0.8826466
A3: 365 | B3: 4226595.6 | C3: 0.33116327 | D3: =IF(C2<=94%,"A",IF(C2<=99%,"B","C")) -> A | E3: =_xlfn.XLOOKUP(A3,'ABC Analysis'!$G:$G,'ABC Analysis'!H:H,,0) -> 70455 | F3: =_xlfn.XLOOKUP(A3,'ABC Analysis'!G:G,'ABC Analysis'!J:J,,0) -> 0.19616442 | G3: =_xlfn.LET(_xlpm.prev,Table3[[#This Row],[Units cum %]]-Table3[[#This Row],[Units]]/SUM(Table3[Units]),IF(_xlpm.prev<0.88,"A",IF(_xlpm.prev<0.987,"B","C"))) -> A | H3: =ABS(CODE(Table3[[#This Row],[Rev class]])-CODE(Table3[[#This Row],[Units class]])) -> 0 | K3: B | L3: =COUNTIF(D:D,"B") -> 57 | M3: =L3/100 -> 0.57 | N3: =SUMIF(Table3[Rev class],"B",Table3[Sales]) -> 1458388.7 | O3: =N3/(SUM(Table3[Sales])) -> 0.044479005 | P3: =SUMIF(Table3[Rev class],"B",Table3[Units]) -> 38128 | Q3: =Table5[[#This Row],[Units (of these products)]]/Table5[[#Totals],[Units (of these products)]] -> 0.10615793
A4: 957 | B4: 3942337.3 | C4: 0.45139956 | D4: =IF(C3<=94%,"A",IF(C3<=99%,"B","C")) -> A | E4: =_xlfn.XLOOKUP(A4,'ABC Analysis'!$G:$G,'ABC Analysis'!H:H,,0) -> 13142 | F4: =_xlfn.XLOOKUP(A4,'ABC Analysis'!G:G,'ABC Analysis'!J:J,,0) -> 0.8826466 | G4: =_xlfn.LET(_xlpm.prev,Table3[[#This Row],[Units cum %]]-Table3[[#This Row],[Units]]/SUM(Table3[Units]),IF(_xlpm.prev<0.88,"A",IF(_xlpm.prev<0.987,"B","C"))) -> A | H4: =ABS(CODE(Table3[[#This Row],[Rev class]])-CODE(Table3[[#This Row],[Units class]])) -> 0 | K4: C | L4: =COUNTIF(D:D,"C") -> 34 | M4: =L4/100 -> 0.34 | N4: =SUMIF(Table3[Rev class],"C",Table3[Sales]) -> 321438.86 | O4: =N4/(SUM(Table3[Sales])) -> 0.0098034772 | P4: =SUMIF(Table3[Rev class],"C",Table3[Units]) -> 4021 | Q4: =Table5[[#This Row],[Units (of these products)]]/Table5[[#Totals],[Units (of these products)]] -> 0.011195474
A5: 191 | B5: 3501149.8 | C5: 0.55818018 | D5: =IF(C4<=94%,"A",IF(C4<=99%,"B","C")) -> A | E5: =_xlfn.XLOOKUP(A5,'ABC Analysis'!$G:$G,'ABC Analysis'!H:H,,0) -> 35015 | F5: =_xlfn.XLOOKUP(A5,'ABC Analysis'!G:G,'ABC Analysis'!J:J,,0) -> 0.61501045 | G5: =_xlfn.LET(_xlpm.prev,Table3[[#This Row],[Units cum %]]-Table3[[#This Row],[Units]]/SUM(Table3[Units]),IF(_xlpm.prev<0.88,"A",IF(_xlpm.prev<0.987,"B","C"))) -> A | H5: =ABS(CODE(Table3[[#This Row],[Rev class]])-CODE(Table3[[#This Row],[Units class]])) -> 0 | K5: Total | L5: =SUM(Table5[Products]) -> 100 | M5: =SUM(Table5[% of product]) -> 1 | N5: =SUM(Table5[Revenue]) -> 32788250 | O5: =SUM(Table5[% of revenue]) -> 1 | P5: =SUM(Table5[Units (of these products)]) -> 359163 | Q5: =SUM(Table5[% of units]) -> 1
A6: 502 | B6: 3007700 | C6: 0.64991122 | D6: =IF(C5<=94%,"A",IF(C5<=99%,"B","C")) -> A | E6: =_xlfn.XLOOKUP(A6,'ABC Analysis'!$G:$G,'ABC Analysis'!H:H,,0) -> 60154 | F6: =_xlfn.XLOOKUP(A6,'ABC Analysis'!G:G,'ABC Analysis'!J:J,,0) -> 0.36364826 | G6: =_xlfn.LET(_xlpm.prev,Table3[[#This Row],[Units cum %]]-Table3[[#This Row],[Units]]/SUM(Table3[Units]),IF(_xlpm.prev<0.88,"A",IF(_xlpm.prev<0.987,"B","C"))) -> A | H6: =ABS(CODE(Table3[[#This Row],[Rev class]])-CODE(Table3[[#This Row],[Units class]])) -> 0
A7: 1073 | B7: 2962851.9 | C7: 0.74027444 | D7: =IF(C6<=94%,"A",IF(C6<=99%,"B","C")) -> A | E7: =_xlfn.XLOOKUP(A7,'ABC Analysis'!$G:$G,'ABC Analysis'!H:H,,0) -> 14815 | F7: =_xlfn.XLOOKUP(A7,'ABC Analysis'!G:G,'ABC Analysis'!J:J,,0) -> 0.84605597 | G7: =_xlfn.LET(_xlpm.prev,Table3[[#This Row],[Units cum %]]-Table3[[#This Row],[Units]]/SUM(Table3[Units]),IF(_xlpm.prev<0.88,"A",IF(_xlpm.prev<0.987,"B","C"))) -> A | H7: =ABS(CODE(Table3[[#This Row],[Rev class]])-CODE(Table3[[#This Row],[Units class]])) -> 0
A8: 1014 | B8: 2762144.7 | C8: 0.82451635 | D8: =IF(C7<=94%,"A",IF(C7<=99%,"B","C")) -> A | E8: =_xlfn.XLOOKUP(A8,'ABC Analysis'!$G:$G,'ABC Analysis'!H:H,,0) -> 55265 | F8: =_xlfn.XLOOKUP(A8,'ABC Analysis'!G:G,'ABC Analysis'!J:J,,0) -> 0.5175199 | G8: =_xlfn.LET(_xlpm.prev,Table3[[#This Row],[Units cum %]]-Table3[[#This Row],[Units]]/SUM(Table3[Units]),IF(_xlpm.prev<0.88,"A",IF(_xlpm.prev<0.987,"B","C"))) -> A | H8: =ABS(CODE(Table3[[#This Row],[Rev class]])-CODE(Table3[[#This Row],[Units class]])) -> 0
A9: 403 | B9: 2760077.8 | C9: 0.90869522 | D9: =IF(C8<=94%,"A",IF(C8<=99%,"B","C")) -> A | E9: =_xlfn.XLOOKUP(A9,'ABC Analysis'!$G:$G,'ABC Analysis'!H:H,,0) -> 21233 | F9: =_xlfn.XLOOKUP(A9,'ABC Analysis'!G:G,'ABC Analysis'!J:J,,0) -> 0.7586444 | G9: =_xlfn.LET(_xlpm.prev,Table3[[#This Row],[Units cum %]]-Table3[[#This Row],[Units]]/SUM(Table3[Units]),IF(_xlpm.prev<0.88,"A",IF(_xlpm.prev<0.987,"B","C"))) -> A | H9: =ABS(CODE(Table3[[#This Row],[Rev class]])-CODE(Table3[[#This Row],[Units class]])) -> 0
A10: 627 | B10: 1213896.5 | C10: 0.94571752 | D10: =IF(C9<=94%,"A",IF(C9<=99%,"B","C")) -> A | E10: =_xlfn.XLOOKUP(A10,'ABC Analysis'!$G:$G,'ABC Analysis'!H:H,,0) -> 30355 | F10: =_xlfn.XLOOKUP(A10,'ABC Analysis'!G:G,'ABC Analysis'!J:J,,0) -> 0.6995264 | G10: =_xlfn.LET(_xlpm.prev,Table3[[#This Row],[Units cum %]]-Table3[[#This Row],[Units]]/SUM(Table3[Units]),IF(_xlpm.prev<0.88,"A",IF(_xlpm.prev<0.987,"B","C"))) -> A | H10: =ABS(CODE(Table3[[#This Row],[Rev class]])-CODE(Table3[[#This Row],[Units class]])) -> 0
A11: 565 | B11: 63490 | C11: 0.94765388 | D11: =IF(C10<=94%,"A",IF(C10<=99%,"B","C")) -> B | E11: =_xlfn.XLOOKUP(A11,'ABC Analysis'!$G:$G,'ABC Analysis'!H:H,,0) -> 907 | F11: =_xlfn.XLOOKUP(A11,'ABC Analysis'!G:G,'ABC Analysis'!J:J,,0) -> 0.89561564 | G11: =_xlfn.LET(_xlpm.prev,Table3[[#This Row],[Units cum %]]-Table3[[#This Row],[Units]]/SUM(Table3[Units]),IF(_xlpm.prev<0.88,"A",IF(_xlpm.prev<0.987,"B","C"))) -> B | H11: =ABS(CODE(Table3[[#This Row],[Rev class]])-CODE(Table3[[#This Row],[Units class]])) -> 0
A12: 728 | B12: 58695 | C12: 0.94944401 | D12: =IF(C11<=94%,"A",IF(C11<=99%,"B","C")) -> B | E12: =_xlfn.XLOOKUP(A12,'ABC Analysis'!$G:$G,'ABC Analysis'!H:H,,0) -> 903 | F12: =_xlfn.XLOOKUP(A12,'ABC Analysis'!G:G,'ABC Analysis'!J:J,,0) -> 0.89812982 | G12: =_xlfn.LET(_xlpm.prev,Table3[[#This Row],[Units cum %]]-Table3[[#This Row],[Units]]/SUM(Table3[Units]),IF(_xlpm.prev<0.88,"A",IF(_xlpm.prev<0.987,"B","C"))) -> B | H12: =ABS(CODE(Table3[[#This Row],[Rev class]])-CODE(Table3[[#This Row],[Units class]])) -> 0
A13: 44 | B13: 54710.882 | C13: 0.95111262 | D13: =IF(C12<=94%,"A",IF(C12<=99%,"B","C")) -> B | E13: =_xlfn.XLOOKUP(A13,'ABC Analysis'!$G:$G,'ABC Analysis'!H:H,,0) -> 912 | F13: =_xlfn.XLOOKUP(A13,'ABC Analysis'!G:G,'ABC Analysis'!J:J,,0) -> 0.89309032 | G13: =_xlfn.LET(_xlpm.prev,Table3[[#This Row],[Units cum %]]-Table3[[#This Row],[Units]]/SUM(Table3[Units]),IF(_xlpm.prev<0.88,"A",IF(_xlpm.prev<0.987,"B","C"))) -> B | H13: =ABS(CODE(Table3[[#This Row],[Rev class]])-CODE(Table3[[#This Row],[Units class]])) -> 0
A14: 823 | B14: 45543.241 | C14: 0.95250163 | D14: =IF(C13<=94%,"A",IF(C13<=99%,"B","C")) -> B | E14: =_xlfn.XLOOKUP(A14,'ABC Analysis'!$G:$G,'ABC Analysis'!H:H,,0) -> 876 | F14: =_xlfn.XLOOKUP(A14,'ABC Analysis'!G:G,'ABC Analysis'!J:J,,0) -> 0.91296152 | G14: =_xlfn.LET(_xlpm.prev,Table3[[#This Row],[Units cum %]]-Table3[[#This Row],[Units]]/SUM(Table3[Units]),IF(_xlpm.prev<0.88,"A",IF(_xlpm.prev<0.987,"B","C"))) -> B | H14: =ABS(CODE(Table3[[#This Row],[Rev class]])-CODE(Table3[[#This Row],[Units class]])) -> 0
A15: 249 | B15: 44195.881 | C15: 0.95384955 | D15: =IF(C14<=94%,"A",IF(C14<=99%,"B","C")) -> B | E15: =_xlfn.XLOOKUP(A15,'ABC Analysis'!$G:$G,'ABC Analysis'!H:H,,0) -> 804 | F15: =_xlfn.XLOOKUP(A15,'ABC Analysis'!G:G,'ABC Analysis'!J:J,,0) -> 0.96912544 | G15: =_xlfn.LET(_xlpm.prev,Table3[[#This Row],[Units cum %]]-Table3[[#This Row],[Units]]/SUM(Table3[Units]),IF(_xlpm.prev<0.88,"A",IF(_xlpm.prev<0.987,"B","C"))) -> B | H15: =ABS(CODE(Table3[[#This Row],[Rev class]])-CODE(Table3[[#This Row],[Units class]])) -> 0
A16: 116 | B16: 42920.461 | C16: 0.95515857 | D16: =IF(C15<=94%,"A",IF(C15<=99%,"B","C")) -> B | E16: =_xlfn.XLOOKUP(A16,'ABC Analysis'!$G:$G,'ABC Analysis'!H:H,,0) -> 954 | F16: =_xlfn.XLOOKUP(A16,'ABC Analysis'!G:G,'ABC Analysis'!J:J,,0) -> 0.88798958 | G16: =_xlfn.LET(_xlpm.prev,Table3[[#This Row],[Units cum %]]-Table3[[#This Row],[Units]]/SUM(Table3[Units]),IF(_xlpm.prev<0.88,"A",IF(_xlpm.prev<0.987,"B","C"))) -> B | H16: =ABS(CODE(Table3[[#This Row],[Rev class]])-CODE(Table3[[#This Row],[Units class]])) -> 0
A17: 821 | B17: 42631.801 | C17: 0.95645878 | D17: =IF(C16<=94%,"A",IF(C16<=99%,"B","C")) -> B | E17: =_xlfn.XLOOKUP(A17,'ABC Analysis'!$G:$G,'ABC Analysis'!H:H,,0) -> 820 | F17: =_xlfn.XLOOKUP(A17,'ABC Analysis'!G:G,'ABC Analysis'!J:J,,0) -> 0.95782973 | G17: =_xlfn.LET(_xlpm.prev,Table3[[#This Row],[Units cum %]]-Table3[[#This Row],[Units]]/SUM(Table3[Units]),IF(_xlpm.prev<0.88,"A",IF(_xlpm.prev<0.987,"B","C"))) -> B | H17: =ABS(CODE(Table3[[#This Row],[Rev class]])-CODE(Table3[[#This Row],[Units class]])) -> 0
... A34: 885 | B34: 22990.8 | C34: 0.97165495 | D34: =IF(C33<=94%,"A",IF(C33<=99%,"B","C")) -> B | E34: =_xlfn.XLOOKUP(A34,'ABC Analysis'!$G:$G,'ABC Analysis'!H:H,,0) -> 920 | F34: =_xlfn.XLOOKUP(A34,'ABC Analysis'!G:G,'ABC Analysis'!J:J,,0) -> 0.89055109 | G34: =_xlfn.LET(_xlpm.prev,Table3[[#This Row],[Units cum %]]-Table3[[#This Row],[Units]]/SUM(Table3[Units]),IF(_xlpm.prev<0.88,"A",IF(_xlpm.prev<0.987,"B","C"))) -> B | H34: =ABS(CODE(Table3[[#This Row],[Rev class]])-CODE(Table3[[#This Row],[Units class]])) -> 0
A35: 724 | B35: 22000 | C35: 0.97232593 | D35: =IF(C34<=94%,"A",IF(C34<=99%,"B","C")) -> B | E35: =_xlfn.XLOOKUP(A35,'ABC Analysis'!$G:$G,'ABC Analysis'!H:H,,0) -> 220 | F35: =_xlfn.XLOOKUP(A35,'ABC Analysis'!G:G,'ABC Analysis'!J:J,,0) -> 0.98960082 | G35: =_xlfn.LET(_xlpm.prev,Table3[[#This Row],[Units cum %]]-Table3[[#This Row],[Units]]/SUM(Table3[Units]),IF(_xlpm.prev<0.88,"A",IF(_xlpm.prev<0.987,"B","C"))) -> C | H35: =ABS(CODE(Table3[[#This Row],[Rev class]])-CODE(Table3[[#This Row],[Units class]])) -> 1 | J35: The dataset is about 165,000 order lines across 100 products over nearly three years. I wanted to know which products actually deserve close inventory attention, so I ran an ABC classification, ranked every product by revenue, built a cumulative percentage, and cut at the 94 and 99 thresholds.
A36: 893 | B36: 21891.24 | C36: 0.97299358 | D36: =IF(C35<=94%,"A",IF(C35<=99%,"B","C")) -> B | E36: =_xlfn.XLOOKUP(A36,'ABC Analysis'!$G:$G,'ABC Analysis'!H:H,,0) -> 876 | F36: =_xlfn.XLOOKUP(A36,'ABC Analysis'!G:G,'ABC Analysis'!J:J,,0) -> 0.91540053 | G36: =_xlfn.LET(_xlpm.prev,Table3[[#This Row],[Units cum %]]-Table3[[#This Row],[Units]]/SUM(Table3[Units]),IF(_xlpm.prev<0.88,"A",IF(_xlpm.prev<0.987,"B","C"))) -> B | H36: =ABS(CODE(Table3[[#This Row],[Rev class]])-CODE(Table3[[#This Row],[Units class]])) -> 0
A37: 906 | B37: 21766.29 | C37: 0.97365743 | D37: =IF(C36<=94%,"A",IF(C36<=99%,"B","C")) -> B | E37: =_xlfn.XLOOKUP(A37,'ABC Analysis'!$G:$G,'ABC Analysis'!H:H,,0) -> 871 | F37: =_xlfn.XLOOKUP(A37,'ABC Analysis'!G:G,'ABC Analysis'!J:J,,0) -> 0.92026462 | G37: =_xlfn.LET(_xlpm.prev,Table3[[#This Row],[Units cum %]]-Table3[[#This Row],[Units]]/SUM(Table3[Units]),IF(_xlpm.prev<0.88,"A",IF(_xlpm.prev<0.987,"B","C"))) -> B | H37: =ABS(CODE(Table3[[#This Row],[Rev class]])-CODE(Table3[[#This Row],[Units class]])) -> 0 | J37: 9 products out of 100 came out A class, carrying 94% of revenue. So roughly 9% of the catalogue drives four-fifths of the business, and those are the items I'd cycle-count weekly and forecast closely. The C tier is 34 products at 5% of revenue, bigger order quantities, quarterly review, not worth the same attention.
A38: 273 | B38: 21244.41 | C38: 0.97430535 | D38: =IF(C37<=94%,"A",IF(C37<=99%,"B","C")) -> B | E38: =_xlfn.XLOOKUP(A38,'ABC Analysis'!$G:$G,'ABC Analysis'!H:H,,0) -> 759 | F38: =_xlfn.XLOOKUP(A38,'ABC Analysis'!G:G,'ABC Analysis'!J:J,,0) -> 0.98422165 | G38: =_xlfn.LET(_xlpm.prev,Table3[[#This Row],[Units cum %]]-Table3[[#This Row],[Units]]/SUM(Table3[Units]),IF(_xlpm.prev<0.88,"A",IF(_xlpm.prev<0.987,"B","C"))) -> B | H38: =ABS(CODE(Table3[[#This Row],[Rev class]])-CODE(Table3[[#This Row],[Units class]])) -> 0
A39: 905 | B39: 21141.54 | C39: 0.97495014 | D39: =IF(C38<=94%,"A",IF(C38<=99%,"B","C")) -> B | E39: =_xlfn.XLOOKUP(A39,'ABC Analysis'!$G:$G,'ABC Analysis'!H:H,,0) -> 846 | F39: =_xlfn.XLOOKUP(A39,'ABC Analysis'!G:G,'ABC Analysis'!J:J,,0) -> 0.93930611 | G39: =_xlfn.LET(_xlpm.prev,Table3[[#This Row],[Units cum %]]-Table3[[#This Row],[Units]]/SUM(Table3[Units]),IF(_xlpm.prev<0.88,"A",IF(_xlpm.prev<0.987,"B","C"))) -> B | H39: =ABS(CODE(Table3[[#This Row],[Rev class]])-CODE(Table3[[#This Row],[Units class]])) -> 0 | J39: I also ran it on units rather than revenue to check whether the revenue view was hiding fast-moving cheap items. It wasn't, because prices in this catalogue are fairly tight, so revenue ranking is mostly tracking volume anyway.
A40: 646 | B40: 20697.93 | C40: 0.9755814 | D40: =IF(C39<=94%,"A",IF(C39<=99%,"B","C")) -> B | E40: =_xlfn.XLOOKUP(A40,'ABC Analysis'!$G:$G,'ABC Analysis'!H:H,,0) -> 207 | F40: =_xlfn.XLOOKUP(A40,'ABC Analysis'!G:G,'ABC Analysis'!J:J,,0) -> 0.99017716 | G40: =_xlfn.LET(_xlpm.prev,Table3[[#This Row],[Units cum %]]-Table3[[#This Row],[Units]]/SUM(Table3[Units]),IF(_xlpm.prev<0.88,"A",IF(_xlpm.prev<0.987,"B","C"))) -> C | H40: =ABS(CODE(Table3[[#This Row],[Rev class]])-CODE(Table3[[#This Row],[Units class]])) -> 1
A41: 886 | B41: 20641.74 | C41: 0.97621095 | D41: =IF(C40<=94%,"A",IF(C40<=99%,"B","C")) -> B | E41: =_xlfn.XLOOKUP(A41,'ABC Analysis'!$G:$G,'ABC Analysis'!H:H,,0) -> 826 | F41: =_xlfn.XLOOKUP(A41,'ABC Analysis'!G:G,'ABC Analysis'!J:J,,0) -> 0.95324685 | G41: =_xlfn.LET(_xlpm.prev,Table3[[#This Row],[Units cum %]]-Table3[[#This Row],[Units]]/SUM(Table3[Units]),IF(_xlpm.prev<0.88,"A",IF(_xlpm.prev<0.987,"B","C"))) -> B | H41: =ABS(CODE(Table3[[#This Row],[Rev class]])-CODE(Table3[[#This Row],[Units class]])) -> 0
A42: 567 | B42: 20475 | C42: 0.97683541 | D42: =IF(C41<=94%,"A",IF(C41<=99%,"B","C")) -> B | E42: =_xlfn.XLOOKUP(A42,'ABC Analysis'!$G:$G,'ABC Analysis'!H:H,,0) -> 819 | F42: =_xlfn.XLOOKUP(A42,'ABC Analysis'!G:G,'ABC Analysis'!J:J,,0) -> 0.96011003 | G42: =_xlfn.LET(_xlpm.prev,Table3[[#This Row],[Units cum %]]-Table3[[#This Row],[Units]]/SUM(Table3[Units]),IF(_xlpm.prev<0.88,"A",IF(_xlpm.prev<0.987,"B","C"))) -> B | H42: =ABS(CODE(Table3[[#This Row],[Rev class]])-CODE(Table3[[#This Row],[Units class]])) -> 0
A43: 778 | B43: 20166.93 | C43: 0.97745048 | D43: =IF(C42<=94%,"A",IF(C42<=99%,"B","C")) -> B | E43: =_xlfn.XLOOKUP(A43,'ABC Analysis'!$G:$G,'ABC Analysis'!H:H,,0) -> 807 | F43: =_xlfn.XLOOKUP(A43,'ABC Analysis'!G:G,'ABC Analysis'!J:J,,0) -> 0.9668869 | G43: =_xlfn.LET(_xlpm.prev,Table3[[#This Row],[Units cum %]]-Table3[[#This Row],[Units]]/SUM(Table3[Units]),IF(_xlpm.prev<0.88,"A",IF(_xlpm.prev<0.987,"B","C"))) -> B | H43: =ABS(CODE(Table3[[#This Row],[Rev class]])-CODE(Table3[[#This Row],[Units class]])) -> 0
A44: 93 | B44: 19917.03 | C44: 0.97805792 | D44: =IF(C43<=94%,"A",IF(C43<=99%,"B","C")) -> B | E44: =_xlfn.XLOOKUP(A44,'ABC Analysis'!$G:$G,'ABC Analysis'!H:H,,0) -> 797 | F44: =_xlfn.XLOOKUP(A44,'ABC Analysis'!G:G,'ABC Analysis'!J:J,,0) -> 0.97134449 | G44: =_xlfn.LET(_xlpm.prev,Table3[[#This Row],[Units cum %]]-Table3[[#This Row],[Units]]/SUM(Table3[Units]),IF(_xlpm.prev<0.88,"A",IF(_xlpm.prev<0.987,"B","C"))) -> B | H44: =ABS(CODE(Table3[[#This Row],[Rev class]])-CODE(Table3[[#This Row],[Units class]])) -> 0
A45: 359 | B45: 19898.01 | C45: 0.97866479 | D45: =IF(C44<=94%,"A",IF(C44<=99%,"B","C")) -> B | E45: =_xlfn.XLOOKUP(A45,'ABC Analysis'!$G:$G,'ABC Analysis'!H:H,,0) -> 199 | F45: =_xlfn.XLOOKUP(A45,'ABC Analysis'!G:G,'ABC Analysis'!J:J,,0) -> 0.99187277 | G45: =_xlfn.LET(_xlpm.prev,Table3[[#This Row],[Units cum %]]-Table3[[#This Row],[Units]]/SUM(Table3[Units]),IF(_xlpm.prev<0.88,"A",IF(_xlpm.prev<0.987,"B","C"))) -> C | H45: =ABS(CODE(Table3[[#This Row],[Rev class]])-CODE(Table3[[#This Row],[Units class]])) -> 1
A46: 917 | B46: 19681.05 | C46: 0.97926503 | D46: =IF(C45<=94%,"A",IF(C45<=99%,"B","C")) -> B | E46: =_xlfn.XLOOKUP(A46,'ABC Analysis'!$G:$G,'ABC Analysis'!H:H,,0) -> 895 | F46: =_xlfn.XLOOKUP(A46,'ABC Analysis'!G:G,'ABC Analysis'!J:J,,0) -> 0.90312755 | G46: =_xlfn.LET(_xlpm.prev,Table3[[#This Row],[Units cum %]]-Table3[[#This Row],[Units]]/SUM(Table3[Units]),IF(_xlpm.prev<0.88,"A",IF(_xlpm.prev<0.987,"B","C"))) -> B | H46: =ABS(CODE(Table3[[#This Row],[Rev class]])-CODE(Table3[[#This Row],[Units class]])) -> 0
A47: 897 | B47: 19642.14 | C47: 0.97986409 | D47: =IF(C46<=94%,"A",IF(C46<=99%,"B","C")) -> B | E47: =_xlfn.XLOOKUP(A47,'ABC Analysis'!$G:$G,'ABC Analysis'!H:H,,0) -> 786 | F47: =_xlfn.XLOOKUP(A47,'ABC Analysis'!G:G,'ABC Analysis'!J:J,,0) -> 0.97353291 | G47: =_xlfn.LET(_xlpm.prev,Table3[[#This Row],[Units cum %]]-Table3[[#This Row],[Units]]/SUM(Table3[Units]),IF(_xlpm.prev<0.88,"A",IF(_xlpm.prev<0.987,"B","C"))) -> B | H47: =ABS(CODE(Table3[[#This Row],[Rev class]])-CODE(Table3[[#This Row],[Units class]])) -> 0
A48: 134 | B48: 19200 | C48: 0.98044967 | D48: =IF(C47<=94%,"A",IF(C47<=99%,"B","C")) -> B | E48: =_xlfn.XLOOKUP(A48,'ABC Analysis'!$G:$G,'ABC Analysis'!H:H,,0) -> 768 | F48: =_xlfn.XLOOKUP(A48,'ABC Analysis'!G:G,'ABC Analysis'!J:J,,0) -> 0.97999237 | G48: =_xlfn.LET(_xlpm.prev,Table3[[#This Row],[Units cum %]]-Table3[[#This Row],[Units]]/SUM(Table3[Units]),IF(_xlpm.prev<0.88,"A",IF(_xlpm.prev<0.987,"B","C"))) -> B | H48: =ABS(CODE(Table3[[#This Row],[Rev class]])-CODE(Table3[[#This Row],[Units class]])) -> 0
A49: 258 | B49: 18903.01 | C49: 0.98102619 | D49: =IF(C48<=94%,"A",IF(C48<=99%,"B","C")) -> B | E49: =_xlfn.XLOOKUP(A49,'ABC Analysis'!$G:$G,'ABC Analysis'!H:H,,0) -> 199 | F49: =_xlfn.XLOOKUP(A49,'ABC Analysis'!G:G,'ABC Analysis'!J:J,,0) -> 0.99242684 | G49: =_xlfn.LET(_xlpm.prev,Table3[[#This Row],[Units cum %]]-Table3[[#This Row],[Units]]/SUM(Table3[Units]),IF(_xlpm.prev<0.88,"A",IF(_xlpm.prev<0.987,"B","C"))) -> C | H49: =ABS(CODE(Table3[[#This Row],[Rev class]])-CODE(Table3[[#This Row],[Units class]])) -> 1
A50: 135 | B50: 18656 | C50: 0.98159517 | D50: =IF(C49<=94%,"A",IF(C49<=99%,"B","C")) -> B | E50: =_xlfn.XLOOKUP(A50,'ABC Analysis'!$G:$G,'ABC Analysis'!H:H,,0) -> 848 | F50: =_xlfn.XLOOKUP(A50,'ABC Analysis'!G:G,'ABC Analysis'!J:J,,0) -> 0.93695063 | G50: =_xlfn.LET(_xlpm.prev,Table3[[#This Row],[Units cum %]]-Table3[[#This Row],[Units]]/SUM(Table3[Units]),IF(_xlpm.prev<0.88,"A",IF(_xlpm.prev<0.987,"B","C"))) -> B | H50: =ABS(CODE(Table3[[#This Row],[Rev class]])-CODE(Table3[[#This Row],[Units class]])) -> 0
A51: 251 | B51: 18627.93 | C51: 0.9821633 | D51: =IF(C50<=94%,"A",IF(C50<=99%,"B","C")) -> B | E51: =_xlfn.XLOOKUP(A51,'ABC Analysis'!$G:$G,'ABC Analysis'!H:H,,0) -> 207 | F51: =_xlfn.XLOOKUP(A51,'ABC Analysis'!G:G,'ABC Analysis'!J:J,,0) -> 0.9907535 | G51: =_xlfn.LET(_xlpm.prev,Table3[[#This Row],[Units cum %]]-Table3[[#This Row],[Units]]/SUM(Table3[Units]),IF(_xlpm.prev<0.88,"A",IF(_xlpm.prev<0.987,"B","C"))) -> C | H51: =ABS(CODE(Table3[[#This Row],[Rev class]])-CODE(Table3[[#This Row],[Units class]])) -> 1
... A101: 60 | B101: 1999.98 | C101: 1 | D101: =IF(C100<=94%,"A",IF(C100<=99%,"B","C")) -> C | E101: =_xlfn.XLOOKUP(A101,'ABC Analysis'!$G:$G,'ABC Analysis'!H:H,,0) -> 2 | F101: =_xlfn.XLOOKUP(A101,'ABC Analysis'!G:G,'ABC Analysis'!J:J,,0) -> 1 | G101: =_xlfn.LET(_xlpm.prev,Table3[[#This Row],[Units cum %]]-Table3[[#This Row],[Units]]/SUM(Table3[Units]),IF(_xlpm.prev<0.88,"A",IF(_xlpm.prev<0.987,"B","C"))) -> C | H101: =ABS(CODE(Table3[[#This Row],[Rev class]])-CODE(Table3[[#This Row],[Units class]])) -> 0

Sheet Simulated on-hand
A1: Simulated on-hand: one row per product (Steps 5–6)
A3: Product ID | B3: Product name | C3: History units | D3: Sept units | E3: Avg daily demand | F3: Seed days | G3: Seed on-hand | H3: Ending on-hand | I3: Sept daily rate | J3: Status | K3: Days of supply | L3: Class | M3: LT | N3: Unit price | O3: SigmaMonthly | P3: SigmaDaily | Q3: Z | R3: SS | S3: ROP | T3: Flag | U3: OverStock $
A4: 725 | B4: LIJA Women's Button Golf Dress | C4: 51 | D4: 2 | E4: 0.55434783 | F4: 108 | G4: =Sim[[#This Row],[Avg daily demand]]*Sim[[#This Row],[Seed days]] -> 59.869565 | H4: =Sim[[#This Row],[Seed on-hand]]-Sim[[#This Row],[Sept units]] -> 57.869565 | I4: =Sim[[#This Row],[Sept units]]/30 -> 0.066666667 | J4: =IF(AND(Sim[[#This Row],[History units]]=0,Sim[[#This Row],[Sept units]]=0),"Inactive",IF(Sim[[#This Row],[History units]]=0,"New - no history",IF(Sim[[#This Row],[Sept units]]=0,"No recent demand",IF(Sim[[#This Row],[Ending on-hand]]<0,"Shortage risk","Normal")))) -> Normal | K4: =IFERROR(Sim[[#This Row],[Ending on-hand]]/Sim[[#This Row],[Sept daily rate]],0) -> 868.04348 | L4: =_xlfn.XLOOKUP(Sim[[#This Row],[Product ID]],Table3[Product ID],Table3[Rev class],,0) -> C | M4: 2.8194444 | N4: 108 | O4: =IFERROR(_xlfn.STDEV.S(_xlfn.XLOOKUP(Sim[[#This Row],[Product ID]],Demand!$A$2:$A$101,Demand!$AD$2:$AG$101)),0) -> 3.6968455 | P4: =Sim[[#This Row],[SigmaMonthly]]/SQRT(30) -> 0.67494856 | Q4: =_xlfn.NORM.S.INV(_xlfn.XLOOKUP(Sim[[#This Row],[Class]],ServiceTbl[Class],ServiceTbl[Level])) -> 1.2815516 | R4: =ROUNDUP(Sim[[#This Row],[Z]]*Sim[[#This Row],[SigmaDaily]]*SQRT(Sim[[#This Row],[LT]]),0) -> 2 | S4: =ROUNDUP(Sim[[#This Row],[Avg daily demand]]*Sim[[#This Row],[LT]]+Sim[[#This Row],[SS]],0) -> 4 | T4: =IF(OR(Sim[[#This Row],[Status]]="Inactive",Sim[[#This Row],[Status]]="New - no history",Sim[[#This Row],[Status]]="No recent demand"),Sim[[#This Row],[Status]],IF(Sim[[#This Row],[Ending on-hand]]<=Sim[[#This Row],[ROP]],"BELOW-ROP",IF(Sim[[#This Row],[Days of supply]]>ExcessDays,IF(Sim[[#This Row],[Sept units]]>=MinVolume,"EXCESS","SLOW-MOVING"),"OK"))) -> SLOW-MOVING | U4: =IF(Sim[[#This Row],[Flag]]="No recent demand",Sim[[#This Row],[Ending on-hand]]*Sim[[#This Row],[Unit price]],IF(OR(Sim[[#This Row],[Flag]]="EXCESS",Sim[[#This Row],[Flag]]="SLOW-MOVING"),(Sim[[#This Row],[Ending on-hand]]-ExcessDays*Sim[[#This Row],[Sept daily rate]])*Sim[[#This Row],[Unit price]],0)) -> 5601.913
A5: 671 | B5: Cleveland Golf Collegiate My Custom Wedge 588 | C5: 42 | D5: 2 | E5: 0.45652174 | F5: 122 | G5: =Sim[[#This Row],[Avg daily demand]]*Sim[[#This Row],[Seed days]] -> 55.695652 | H5: =Sim[[#This Row],[Seed on-hand]]-Sim[[#This Row],[Sept units]] -> 53.695652 | I5: =Sim[[#This Row],[Sept units]]/30 -> 0.066666667 | J5: =IF(AND(Sim[[#This Row],[History units]]=0,Sim[[#This Row],[Sept units]]=0),"Inactive",IF(Sim[[#This Row],[History units]]=0,"New - no history",IF(Sim[[#This Row],[Sept units]]=0,"No recent demand",IF(Sim[[#This Row],[Ending on-hand]]<0,"Shortage risk","Normal")))) -> Normal | K5: =IFERROR(Sim[[#This Row],[Ending on-hand]]/Sim[[#This Row],[Sept daily rate]],0) -> 805.43478 | L5: =_xlfn.XLOOKUP(Sim[[#This Row],[Product ID]],Table3[Product ID],Table3[Rev class],,0) -> C | M5: 3.0645161 | N5: 209.99001 | O5: =IFERROR(_xlfn.STDEV.S(_xlfn.XLOOKUP(Sim[[#This Row],[Product ID]],Demand!$A$2:$A$101,Demand!$AD$2:$AG$101)),0) -> 2.2173558 | P5: =Sim[[#This Row],[SigmaMonthly]]/SQRT(30) -> 0.40483193 | Q5: =_xlfn.NORM.S.INV(_xlfn.XLOOKUP(Sim[[#This Row],[Class]],ServiceTbl[Class],ServiceTbl[Level])) -> 1.2815516 | R5: =ROUNDUP(Sim[[#This Row],[Z]]*Sim[[#This Row],[SigmaDaily]]*SQRT(Sim[[#This Row],[LT]]),0) -> 1 | S5: =ROUNDUP(Sim[[#This Row],[Avg daily demand]]*Sim[[#This Row],[LT]]+Sim[[#This Row],[SS]],0) -> 3 | T5: =IF(OR(Sim[[#This Row],[Status]]="Inactive",Sim[[#This Row],[Status]]="New - no history",Sim[[#This Row],[Status]]="No recent demand"),Sim[[#This Row],[Status]],IF(Sim[[#This Row],[Ending on-hand]]<=Sim[[#This Row],[ROP]],"BELOW-ROP",IF(Sim[[#This Row],[Days of supply]]>ExcessDays,IF(Sim[[#This Row],[Sept units]]>=MinVolume,"EXCESS","SLOW-MOVING"),"OK"))) -> SLOW-MOVING | U5: =IF(Sim[[#This Row],[Flag]]="No recent demand",Sim[[#This Row],[Ending on-hand]]*Sim[[#This Row],[Unit price]],IF(OR(Sim[[#This Row],[Flag]]="EXCESS",Sim[[#This Row],[Flag]]="SLOW-MOVING"),(Sim[[#This Row],[Ending on-hand]]-ExcessDays*Sim[[#This Row],[Sept daily rate]])*Sim[[#This Row],[Unit price]],0)) -> 10015.61
A6: 625 | B6: Nike Men's Kobe IX Elite Low Basketball Shoe | C6: 37 | D6: 2 | E6: 0.40217391 | F6: 144 | G6: =Sim[[#This Row],[Avg daily demand]]*Sim[[#This Row],[Seed days]] -> 57.913043 | H6: =Sim[[#This Row],[Seed on-hand]]-Sim[[#This Row],[Sept units]] -> 55.913043 | I6: =Sim[[#This Row],[Sept units]]/30 -> 0.066666667 | J6: =IF(AND(Sim[[#This Row],[History units]]=0,Sim[[#This Row],[Sept units]]=0),"Inactive",IF(Sim[[#This Row],[History units]]=0,"New - no history",IF(Sim[[#This Row],[Sept units]]=0,"No recent demand",IF(Sim[[#This Row],[Ending on-hand]]<0,"Shortage risk","Normal")))) -> Normal | K6: =IFERROR(Sim[[#This Row],[Ending on-hand]]/Sim[[#This Row],[Sept daily rate]],0) -> 838.69565 | L6: =_xlfn.XLOOKUP(Sim[[#This Row],[Product ID]],Table3[Product ID],Table3[Rev class],,0) -> C | M6: 3.0677966 | N6: 199.99001 | O6: =IFERROR(_xlfn.STDEV.S(_xlfn.XLOOKUP(Sim[[#This Row],[Product ID]],Demand!$A$2:$A$101,Demand!$AD$2:$AG$101)),0) -> 5.7445626 | P6: =Sim[[#This Row],[SigmaMonthly]]/SQRT(30) -> 1.0488088 | Q6: =_xlfn.NORM.S.INV(_xlfn.XLOOKUP(Sim[[#This Row],[Class]],ServiceTbl[Class],ServiceTbl[Level])) -> 1.2815516 | R6: =ROUNDUP(Sim[[#This Row],[Z]]*Sim[[#This Row],[SigmaDaily]]*SQRT(Sim[[#This Row],[LT]]),0) -> 3 | S6: =ROUNDUP(Sim[[#This Row],[Avg daily demand]]*Sim[[#This Row],[LT]]+Sim[[#This Row],[SS]],0) -> 5 | T6: =IF(OR(Sim[[#This Row],[Status]]="Inactive",Sim[[#This Row],[Status]]="New - no history",Sim[[#This Row],[Status]]="No recent demand"),Sim[[#This Row],[Status]],IF(Sim[[#This Row],[Ending on-hand]]<=Sim[[#This Row],[ROP]],"BELOW-ROP",IF(Sim[[#This Row],[Days of supply]]>ExcessDays,IF(Sim[[#This Row],[Sept units]]>=MinVolume,"EXCESS","SLOW-MOVING"),"OK"))) -> SLOW-MOVING | U6: =IF(Sim[[#This Row],[Flag]]="No recent demand",Sim[[#This Row],[Ending on-hand]]*Sim[[#This Row],[Unit price]],IF(OR(Sim[[#This Row],[Flag]]="EXCESS",Sim[[#This Row],[Flag]]="SLOW-MOVING"),(Sim[[#This Row],[Ending on-hand]]-ExcessDays*Sim[[#This Row],[Sept daily rate]])*Sim[[#This Row],[Unit price]],0)) -> 9982.1098
A7: 982 | B7: insta-bed Neverflat Air Mattress | C7: 35 | D7: 2 | E7: 0.38043478 | F7: 14 | G7: =Sim[[#This Row],[Avg daily demand]]*Sim[[#This Row],[Seed days]] -> 5.326087 | H7: =Sim[[#This Row],[Seed on-hand]]-Sim[[#This Row],[Sept units]] -> 3.326087 | I7: =Sim[[#This Row],[Sept units]]/30 -> 0.066666667 | J7: =IF(AND(Sim[[#This Row],[History units]]=0,Sim[[#This Row],[Sept units]]=0),"Inactive",IF(Sim[[#This Row],[History units]]=0,"New - no history",IF(Sim[[#This Row],[Sept units]]=0,"No recent demand",IF(Sim[[#This Row],[Ending on-hand]]<0,"Shortage risk","Normal")))) -> Normal | K7: =IFERROR(Sim[[#This Row],[Ending on-hand]]/Sim[[#This Row],[Sept daily rate]],0) -> 49.891304 | L7: =_xlfn.XLOOKUP(Sim[[#This Row],[Product ID]],Table3[Product ID],Table3[Rev class],,0) -> C | M7: 2.862069 | N7: 149.99001 | O7: =IFERROR(_xlfn.STDEV.S(_xlfn.XLOOKUP(Sim[[#This Row],[Product ID]],Demand!$A$2:$A$101,Demand!$AD$2:$AG$101)),0) -> 4.4347116 | P7: =Sim[[#This Row],[SigmaMonthly]]/SQRT(30) -> 0.80966385 | Q7: =_xlfn.NORM.S.INV(_xlfn.XLOOKUP(Sim[[#This Row],[Class]],ServiceTbl[Class],ServiceTbl[Level])) -> 1.2815516 | R7: =ROUNDUP(Sim[[#This Row],[Z]]*Sim[[#This Row],[SigmaDaily]]*SQRT(Sim[[#This Row],[LT]]),0) -> 2 | S7: =ROUNDUP(Sim[[#This Row],[Avg daily demand]]*Sim[[#This Row],[LT]]+Sim[[#This Row],[SS]],0) -> 4 | T7: =IF(OR(Sim[[#This Row],[Status]]="Inactive",Sim[[#This Row],[Status]]="New - no history",Sim[[#This Row],[Status]]="No recent demand"),Sim[[#This Row],[Status]],IF(Sim[[#This Row],[Ending on-hand]]<=Sim[[#This Row],[ROP]],"BELOW-ROP",IF(Sim[[#This Row],[Days of supply]]>ExcessDays,IF(Sim[[#This Row],[Sept units]]>=MinVolume,"EXCESS","SLOW-MOVING"),"OK"))) -> BELOW-ROP | U7: =IF(Sim[[#This Row],[Flag]]="No recent demand",Sim[[#This Row],[Ending on-hand]]*Sim[[#This Row],[Unit price]],IF(OR(Sim[[#This Row],[Flag]]="EXCESS",Sim[[#This Row],[Flag]]="SLOW-MOVING"),(Sim[[#This Row],[Ending on-hand]]-ExcessDays*Sim[[#This Row],[Sept daily rate]])*Sim[[#This Row],[Unit price]],0)) -> 0
A8: 705 | B8: Cleveland Golf Women's 588 RTX CB Satin Chrom | C8: 48 | D8: 3 | E8: 0.52173913 | F8: 72 | G8: =Sim[[#This Row],[Avg daily demand]]*Sim[[#This Row],[Seed days]] -> 37.565217 | H8: =Sim[[#This Row],[Seed on-hand]]-Sim[[#This Row],[Sept units]] -> 34.565217 | I8: =Sim[[#This Row],[Sept units]]/30 -> 0.1 | J8: =IF(AND(Sim[[#This Row],[History units]]=0,Sim[[#This Row],[Sept units]]=0),"Inactive",IF(Sim[[#This Row],[History units]]=0,"New - no history",IF(Sim[[#This Row],[Sept units]]=0,"No recent demand",IF(Sim[[#This Row],[Ending on-hand]]<0,"Shortage risk","Normal")))) -> Normal | K8: =IFERROR(Sim[[#This Row],[Ending on-hand]]/Sim[[#This Row],[Sept daily rate]],0) -> 345.65217 | L8: =_xlfn.XLOOKUP(Sim[[#This Row],[Product ID]],Table3[Product ID],Table3[Rev class],,0) -> C | M8: 3.0882353 | N8: 119.99 | O8: =IFERROR(_xlfn.STDEV.S(_xlfn.XLOOKUP(Sim[[#This Row],[Product ID]],Demand!$A$2:$A$101,Demand!$AD$2:$AG$101)),0) -> 3.7749172 | P8: =Sim[[#This Row],[SigmaMonthly]]/SQRT(30) -> 0.68920244 | Q8: =_xlfn.NORM.S.INV(_xlfn.XLOOKUP(Sim[[#This Row],[Class]],ServiceTbl[Class],ServiceTbl[Level])) -> 1.2815516 | R8: =ROUNDUP(Sim[[#This Row],[Z]]*Sim[[#This Row],[SigmaDaily]]*SQRT(Sim[[#This Row],[LT]]),0) -> 2 | S8: =ROUNDUP(Sim[[#This Row],[Avg daily demand]]*Sim[[#This Row],[LT]]+Sim[[#This Row],[SS]],0) -> 4 | T8: =IF(OR(Sim[[#This Row],[Status]]="Inactive",Sim[[#This Row],[Status]]="New - no history",Sim[[#This Row],[Status]]="No recent demand"),Sim[[#This Row],[Status]],IF(Sim[[#This Row],[Ending on-hand]]<=Sim[[#This Row],[ROP]],"BELOW-ROP",IF(Sim[[#This Row],[Days of supply]]>ExcessDays,IF(Sim[[#This Row],[Sept units]]>=MinVolume,"EXCESS","SLOW-MOVING"),"OK"))) -> SLOW-MOVING | U8: =IF(Sim[[#This Row],[Flag]]="No recent demand",Sim[[#This Row],[Ending on-hand]]*Sim[[#This Row],[Unit price]],IF(OR(Sim[[#This Row],[Flag]]="EXCESS",Sim[[#This Row],[Flag]]="SLOW-MOVING"),(Sim[[#This Row],[Ending on-hand]]-ExcessDays*Sim[[#This Row],[Sept daily rate]])*Sim[[#This Row],[Unit price]],0)) -> 3067.5704
A9: 216 | B9: Yakima DoubleDown Ace Hitch Mount 4-Bike Rack | C9: 48 | D9: 3 | E9: 0.52173913 | F9: 137 | G9: =Sim[[#This Row],[Avg daily demand]]*Sim[[#This Row],[Seed days]] -> 71.478261 | H9: =Sim[[#This Row],[Seed on-hand]]-Sim[[#This Row],[Sept units]] -> 68.478261 | I9: =Sim[[#This Row],[Sept units]]/30 -> 0.1 | J9: =IF(AND(Sim[[#This Row],[History units]]=0,Sim[[#This Row],[Sept units]]=0),"Inactive",IF(Sim[[#This Row],[History units]]=0,"New - no history",IF(Sim[[#This Row],[Sept units]]=0,"No recent demand",IF(Sim[[#This Row],[Ending on-hand]]<0,"Shortage risk","Normal")))) -> Normal | K9: =IFERROR(Sim[[#This Row],[Ending on-hand]]/Sim[[#This Row],[Sept daily rate]],0) -> 684.78261 | L9: =_xlfn.XLOOKUP(Sim[[#This Row],[Product ID]],Table3[Product ID],Table3[Rev class],,0) -> C | M9: 2.983871 | N9: 189 | O9: =IFERROR(_xlfn.STDEV.S(_xlfn.XLOOKUP(Sim[[#This Row],[Product ID]],Demand!$A$2:$A$101,Demand!$AD$2:$AG$101)),0) -> 5.7373048 | P9: =Sim[[#This Row],[SigmaMonthly]]/SQRT(30) -> 1.0474838 | Q9: =_xlfn.NORM.S.INV(_xlfn.XLOOKUP(Sim[[#This Row],[Class]],ServiceTbl[Class],ServiceTbl[Level])) -> 1.2815516 | R9: =ROUNDUP(Sim[[#This Row],[Z]]*Sim[[#This Row],[SigmaDaily]]*SQRT(Sim[[#This Row],[LT]]),0) -> 3 | S9: =ROUNDUP(Sim[[#This Row],[Avg daily demand]]*Sim[[#This Row],[LT]]+Sim[[#This Row],[SS]],0) -> 5 | T9: =IF(OR(Sim[[#This Row],[Status]]="Inactive",Sim[[#This Row],[Status]]="New - no history",Sim[[#This Row],[Status]]="No recent demand"),Sim[[#This Row],[Status]],IF(Sim[[#This Row],[Ending on-hand]]<=Sim[[#This Row],[ROP]],"BELOW-ROP",IF(Sim[[#This Row],[Days of supply]]>ExcessDays,IF(Sim[[#This Row],[Sept units]]>=MinVolume,"EXCESS","SLOW-MOVING"),"OK"))) -> SLOW-MOVING | U9: =IF(Sim[[#This Row],[Flag]]="No recent demand",Sim[[#This Row],[Ending on-hand]]*Sim[[#This Row],[Unit price]],IF(OR(Sim[[#This Row],[Flag]]="EXCESS",Sim[[#This Row],[Flag]]="SLOW-MOVING"),(Sim[[#This Row],[Ending on-hand]]-ExcessDays*Sim[[#This Row],[Sept daily rate]])*Sim[[#This Row],[Unit price]],0)) -> 11241.391
A10: 24 | B10: Elevation Training Mask 2.0 | C10: 139 | D10: 9 | E10: 1.5108696 | F10: 44 | G10: =Sim[[#This Row],[Avg daily demand]]*Sim[[#This Row],[Seed days]] -> 66.478261 | H10: =Sim[[#This Row],[Seed on-hand]]-Sim[[#This Row],[Sept units]] -> 57.478261 | I10: =Sim[[#This Row],[Sept units]]/30 -> 0.3 | J10: =IF(AND(Sim[[#This Row],[History units]]=0,Sim[[#This Row],[Sept units]]=0),"Inactive",IF(Sim[[#This Row],[History units]]=0,"New - no history",IF(Sim[[#This Row],[Sept units]]=0,"No recent demand",IF(Sim[[#This Row],[Ending on-hand]]<0,"Shortage risk","Normal")))) -> Normal | K10: =IFERROR(Sim[[#This Row],[Ending on-hand]]/Sim[[#This Row],[Sept daily rate]],0) -> 191.5942 | L10: =_xlfn.XLOOKUP(Sim[[#This Row],[Product ID]],Table3[Product ID],Table3[Rev class],,0) -> B | M10: 3.0547945 | N10: 79.989998 | O10: =IFERROR(_xlfn.STDEV.S(_xlfn.XLOOKUP(Sim[[#This Row],[Product ID]],Demand!$A$2:$A$101,Demand!$AD$2:$AG$101)),0) -> 12.55322 | P10: =Sim[[#This Row],[SigmaMonthly]]/SQRT(30) -> 2.2918939 | Q10: =_xlfn.NORM.S.INV(_xlfn.XLOOKUP(Sim[[#This Row],[Class]],ServiceTbl[Class],ServiceTbl[Level])) -> 1.6448536 | R10: =ROUNDUP(Sim[[#This Row],[Z]]*Sim[[#This Row],[SigmaDaily]]*SQRT(Sim[[#This Row],[LT]]),0) -> 7 | S10: =ROUNDUP(Sim[[#This Row],[Avg daily demand]]*Sim[[#This Row],[LT]]+Sim[[#This Row],[SS]],0) -> 12 | T10: =IF(OR(Sim[[#This Row],[Status]]="Inactive",Sim[[#This Row],[Status]]="New - no history",Sim[[#This Row],[Status]]="No recent demand"),Sim[[#This Row],[Status]],IF(Sim[[#This Row],[Ending on-hand]]<=Sim[[#This Row],[ROP]],"BELOW-ROP",IF(Sim[[#This Row],[Days of supply]]>ExcessDays,IF(Sim[[#This Row],[Sept units]]>=MinVolume,"EXCESS","SLOW-MOVING"),"OK"))) -> SLOW-MOVING | U10: =IF(Sim[[#This Row],[Flag]]="No recent demand",Sim[[#This Row],[Ending on-hand]]*Sim[[#This Row],[Unit price]],IF(OR(Sim[[#This Row],[Flag]]="EXCESS",Sim[[#This Row],[Flag]]="SLOW-MOVING"),(Sim[[#This Row],[Ending on-hand]]-ExcessDays*Sim[[#This Row],[Sept daily rate]])*Sim[[#This Row],[Unit price]],0)) -> 2437.956
A11: 666 | B11: Merrell Men's All Out Flash Trail Running Sho | C11: 61 | D11: 4 | E11: 0.66304348 | F11: 112 | G11: =Sim[[#This Row],[Avg daily demand]]*Sim[[#This Row],[Seed days]] -> 74.26087 | H11: =Sim[[#This Row],[Seed on-hand]]-Sim[[#This Row],[Sept units]] -> 70.26087 | I11: =Sim[[#This Row],[Sept units]]/30 -> 0.13333333 | J11: =IF(AND(Sim[[#This Row],[History units]]=0,Sim[[#This Row],[Sept units]]=0),"Inactive",IF(Sim[[#This Row],[History units]]=0,"New - no history",IF(Sim[[#This Row],[Sept units]]=0,"No recent demand",IF(Sim[[#This Row],[Ending on-hand]]<0,"Shortage risk","Normal")))) -> Normal | K11: =IFERROR(Sim[[#This Row],[Ending on-hand]]/Sim[[#This Row],[Sept daily rate]],0) -> 526.95652 | L11: =_xlfn.XLOOKUP(Sim[[#This Row],[Product ID]],Table3[Product ID],Table3[Rev class],,0) -> C | M11: 3.1325301 | N11: 109.99 | O11: =IFERROR(_xlfn.STDEV.S(_xlfn.XLOOKUP(Sim[[#This Row],[Product ID]],Demand!$A$2:$A$101,Demand!$AD$2:$AG$101)),0) -> 5.3541261 | P11: =Sim[[#This Row],[SigmaMonthly]]/SQRT(30) -> 0.97752522 | Q11: =_xlfn.NORM.S.INV(_xlfn.XLOOKUP(Sim[[#This Row],[Class]],ServiceTbl[Class],ServiceTbl[Level])) -> 1.2815516 | R11: =ROUNDUP(Sim[[#This Row],[Z]]*Sim[[#This Row],[SigmaDaily]]*SQRT(Sim[[#This Row],[LT]]),0) -> 3 | S11: =ROUNDUP(Sim[[#This Row],[Avg daily demand]]*Sim[[#This Row],[LT]]+Sim[[#This Row],[SS]],0) -> 6 | T11: =IF(OR(Sim[[#This Row],[Status]]="Inactive",Sim[[#This Row],[Status]]="New - no history",Sim[[#This Row],[Status]]="No recent demand"),Sim[[#This Row],[Status]],IF(Sim[[#This Row],[Ending on-hand]]<=Sim[[#This Row],[ROP]],"BELOW-ROP",IF(Sim[[#This Row],[Days of supply]]>ExcessDays,IF(Sim[[#This Row],[Sept units]]>=MinVolume,"EXCESS","SLOW-MOVING"),"OK"))) -> SLOW-MOVING | U11: =IF(Sim[[#This Row],[Flag]]="No recent demand",Sim[[#This Row],[Ending on-hand]]*Sim[[#This Row],[Unit price]],IF(OR(Sim[[#This Row],[Flag]]="EXCESS",Sim[[#This Row],[Flag]]="SLOW-MOVING"),(Sim[[#This Row],[Ending on-hand]]-ExcessDays*Sim[[#This Row],[Sept daily rate]])*Sim[[#This Row],[Unit price]],0)) -> 6408.1129
A12: 786 | B12: TaylorMade 2014 Purelite Stand Bag | C12: 42 | D12: 3 | E12: 0.45652174 | F12: 138 | G12: =Sim[[#This Row],[Avg daily demand]]*Sim[[#This Row],[Seed days]] -> 63 | H12: =Sim[[#This Row],[Seed on-hand]]-Sim[[#This Row],[Sept units]] -> 60 | I12: =Sim[[#This Row],[Sept units]]/30 -> 0.1 | J12: =IF(AND(Sim[[#This Row],[History units]]=0,Sim[[#This Row],[Sept units]]=0),"Inactive",IF(Sim[[#This Row],[History units]]=0,"New - no history",IF(Sim[[#This Row],[Sept units]]=0,"No recent demand",IF(Sim[[#This Row],[Ending on-hand]]<0,"Shortage risk","Normal")))) -> Normal | K12: =IFERROR(Sim[[#This Row],[Ending on-hand]]/Sim[[#This Row],[Sept daily rate]],0) -> 600 | L12: =_xlfn.XLOOKUP(Sim[[#This Row],[Product ID]],Table3[Product ID],Table3[Rev class],,0) -> C | M12: 2.8730159 | N12: 179.99001 | O12: =IFERROR(_xlfn.STDEV.S(_xlfn.XLOOKUP(Sim[[#This Row],[Product ID]],Demand!$A$2:$A$101,Demand!$AD$2:$AG$101)),0) -> 0.81649658 | P12: =Sim[[#This Row],[SigmaMonthly]]/SQRT(30) -> 0.1490712 | Q12: =_xlfn.NORM.S.INV(_xlfn.XLOOKUP(Sim[[#This Row],[Class]],ServiceTbl[Class],ServiceTbl[Level])) -> 1.2815516 | R12: =ROUNDUP(Sim[[#This Row],[Z]]*Sim[[#This Row],[SigmaDaily]]*SQRT(Sim[[#This Row],[LT]]),0) -> 1 | S12: =ROUNDUP(Sim[[#This Row],[Avg daily demand]]*Sim[[#This Row],[LT]]+Sim[[#This Row],[SS]],0) -> 3 | T12: =IF(OR(Sim[[#This Row],[Status]]="Inactive",Sim[[#This Row],[Status]]="New - no history",Sim[[#This Row],[Status]]="No recent demand"),Sim[[#This Row],[Status]],IF(Sim[[#This Row],[Ending on-hand]]<=Sim[[#This Row],[ROP]],"BELOW-ROP",IF(Sim[[#This Row],[Days of supply]]>ExcessDays,IF(Sim[[#This Row],[Sept units]]>=MinVolume,"EXCESS","SLOW-MOVING"),"OK"))) -> SLOW-MOVING | U12: =IF(Sim[[#This Row],[Flag]]="No recent demand",Sim[[#This Row],[Ending on-hand]]*Sim[[#This Row],[Unit price]],IF(OR(Sim[[#This Row],[Flag]]="EXCESS",Sim[[#This Row],[Flag]]="SLOW-MOVING"),(Sim[[#This Row],[Ending on-hand]]-ExcessDays*Sim[[#This Row],[Sept daily rate]])*Sim[[#This Row],[Unit price]],0)) -> 9179.4903
A13: 858 | B13: GolfBuddy VT3 GPS Watch | C13: 37 | D13: 3 | E13: 0.40217391 | F13: 16 | G13: =Sim[[#This Row],[Avg daily demand]]*Sim[[#This Row],[Seed days]] -> 6.4347826 | H13: =Sim[[#This Row],[Seed on-hand]]-Sim[[#This Row],[Sept units]] -> 3.4347826 | I13: =Sim[[#This Row],[Sept units]]/30 -> 0.1 | J13: =IF(AND(Sim[[#This Row],[History units]]=0,Sim[[#This Row],[Sept units]]=0),"Inactive",IF(Sim[[#This Row],[History units]]=0,"New - no history",IF(Sim[[#This Row],[Sept units]]=0,"No recent demand",IF(Sim[[#This Row],[Ending on-hand]]<0,"Shortage risk","Normal")))) -> Normal | K13: =IFERROR(Sim[[#This Row],[Ending on-hand]]/Sim[[#This Row],[Sept daily rate]],0) -> 34.347826 | L13: =_xlfn.XLOOKUP(Sim[[#This Row],[Product ID]],Table3[Product ID],Table3[Rev class],,0) -> C | M13: 2.9464286 | N13: 199.99001 | O13: =IFERROR(_xlfn.STDEV.S(_xlfn.XLOOKUP(Sim[[#This Row],[Product ID]],Demand!$A$2:$A$101,Demand!$AD$2:$AG$101)),0) -> 1.8929694 | P13: =Sim[[#This Row],[SigmaMonthly]]/SQRT(30) -> 0.34560736 | Q13: =_xlfn.NORM.S.INV(_xlfn.XLOOKUP(Sim[[#This Row],[Class]],ServiceTbl[Class],ServiceTbl[Level])) -> 1.2815516 | R13: =ROUNDUP(Sim[[#This Row],[Z]]*Sim[[#This Row],[SigmaDaily]]*SQRT(Sim[[#This Row],[LT]]),0) -> 1 | S13: =ROUNDUP(Sim[[#This Row],[Avg daily demand]]*Sim[[#This Row],[LT]]+Sim[[#This Row],[SS]],0) -> 3 | T13: =IF(OR(Sim[[#This Row],[Status]]="Inactive",Sim[[#This Row],[Status]]="New - no history",Sim[[#This Row],[Status]]="No recent demand"),Sim[[#This Row],[Status]],IF(Sim[[#This Row],[Ending on-hand]]<=Sim[[#This Row],[ROP]],"BELOW-ROP",IF(Sim[[#This Row],[Days of supply]]>ExcessDays,IF(Sim[[#This Row],[Sept units]]>=MinVolume,"EXCESS","SLOW-MOVING"),"OK"))) -> OK | U13: =IF(Sim[[#This Row],[Flag]]="No recent demand",Sim[[#This Row],[Ending on-hand]]*Sim[[#This Row],[Unit price]],IF(OR(Sim[[#This Row],[Flag]]="EXCESS",Sim[[#This Row],[Flag]]="SLOW-MOVING"),(Sim[[#This Row],[Ending on-hand]]-ExcessDays*Sim[[#This Row],[Sept daily rate]])*Sim[[#This Row],[Unit price]],0)) -> 0
A14: 652 | B14: Merrell Women's Grassbow Sport Waterproof Hik | C14: 36 | D14: 3 | E14: 0.39130435 | F14: 105 | G14: =Sim[[#This Row],[Avg daily demand]]*Sim[[#This Row],[Seed days]] -> 41.086957 | H14: =Sim[[#This Row],[Seed on-hand]]-Sim[[#This Row],[Sept units]] -> 38.086957 | I14: =Sim[[#This Row],[Sept units]]/30 -> 0.1 | J14: =IF(AND(Sim[[#This Row],[History units]]=0,Sim[[#This Row],[Sept units]]=0),"Inactive",IF(Sim[[#This Row],[History units]]=0,"New - no history",IF(Sim[[#This Row],[Sept units]]=0,"No recent demand",IF(Sim[[#This Row],[Ending on-hand]]<0,"Shortage risk","Normal")))) -> Normal | K14: =IFERROR(Sim[[#This Row],[Ending on-hand]]/Sim[[#This Row],[Sept daily rate]],0) -> 380.86957 | L14: =_xlfn.XLOOKUP(Sim[[#This Row],[Product ID]],Table3[Product ID],Table3[Rev class],,0) -> C | M14: 3.0740741 | N14: 129.99001 | O14: =IFERROR(_xlfn.STDEV.S(_xlfn.XLOOKUP(Sim[[#This Row],[Product ID]],Demand!$A$2:$A$101,Demand!$AD$2:$AG$101)),0) -> 2.2173558 | P14: =Sim[[#This Row],[SigmaMonthly]]/SQRT(30) -> 0.40483193 | Q14: =_xlfn.NORM.S.INV(_xlfn.XLOOKUP(Sim[[#This Row],[Class]],ServiceTbl[Class],ServiceTbl[Level])) -> 1.2815516 | R14: =ROUNDUP(Sim[[#This Row],[Z]]*Sim[[#This Row],[SigmaDaily]]*SQRT(Sim[[#This Row],[LT]]),0) -> 1 | S14: =ROUNDUP(Sim[[#This Row],[Avg daily demand]]*Sim[[#This Row],[LT]]+Sim[[#This Row],[SS]],0) -> 3 | T14: =IF(OR(Sim[[#This Row],[Status]]="Inactive",Sim[[#This Row],[Status]]="New - no history",Sim[[#This Row],[Status]]="No recent demand"),Sim[[#This Row],[Status]],IF(Sim[[#This Row],[Ending on-hand]]<=Sim[[#This Row],[ROP]],"BELOW-ROP",IF(Sim[[#This Row],[Days of supply]]>ExcessDays,IF(Sim[[#This Row],[Sept units]]>=MinVolume,"EXCESS","SLOW-MOVING"),"OK"))) -> SLOW-MOVING | U14: =IF(Sim[[#This Row],[Flag]]="No recent demand",Sim[[#This Row],[Ending on-hand]]*Sim[[#This Row],[Unit price]],IF(OR(Sim[[#This Row],[Flag]]="EXCESS",Sim[[#This Row],[Flag]]="SLOW-MOVING"),(Sim[[#This Row],[Ending on-hand]]-ExcessDays*Sim[[#This Row],[Sept daily rate]])*Sim[[#This Row],[Unit price]],0)) -> 3781.0136
A15: 607 | B15: Garmin Approach S3 Golf GPS Watch | C15: 47 | D15: 4 | E15: 0.51086957 | F15: 78 | G15: =Sim[[#This Row],[Avg daily demand]]*Sim[[#This Row],[Seed days]] -> 39.847826 | H15: =Sim[[#This Row],[Seed on-hand]]-Sim[[#This Row],[Sept units]] -> 35.847826 | I15: =Sim[[#This Row],[Sept units]]/30 -> 0.13333333 | J15: =IF(AND(Sim[[#This Row],[History units]]=0,Sim[[#This Row],[Sept units]]=0),"Inactive",IF(Sim[[#This Row],[History units]]=0,"New - no history",IF(Sim[[#This Row],[Sept units]]=0,"No recent demand",IF(Sim[[#This Row],[Ending on-hand]]<0,"Shortage risk","Normal")))) -> Normal | K15: =IFERROR(Sim[[#This Row],[Ending on-hand]]/Sim[[#This Row],[Sept daily rate]],0) -> 268.8587 | L15: =_xlfn.XLOOKUP(Sim[[#This Row],[Product ID]],Table3[Product ID],Table3[Rev class],,0) -> B | M15: 3.0810811 | N15: 249.99001 | O15: =IFERROR(_xlfn.STDEV.S(_xlfn.XLOOKUP(Sim[[#This Row],[Product ID]],Demand!$A$2:$A$101,Demand!$AD$2:$AG$101)),0) -> 6.6520673 | P15: =Sim[[#This Row],[SigmaMonthly]]/SQRT(30) -> 1.2144958 | Q15: =_xlfn.NORM.S.INV(_xlfn.XLOOKUP(Sim[[#This Row],[Class]],ServiceTbl[Class],ServiceTbl[Level])) -> 1.6448536 | R15: =ROUNDUP(Sim[[#This Row],[Z]]*Sim[[#This Row],[SigmaDaily]]*SQRT(Sim[[#This Row],[LT]]),0) -> 4 | S15: =ROUNDUP(Sim[[#This Row],[Avg daily demand]]*Sim[[#This Row],[LT]]+Sim[[#This Row],[SS]],0) -> 6 | T15: =IF(OR(Sim[[#This Row],[Status]]="Inactive",Sim[[#This Row],[Status]]="New - no history",Sim[[#This Row],[Status]]="No recent demand"),Sim[[#This Row],[Status]],IF(Sim[[#This Row],[Ending on-hand]]<=Sim[[#This Row],[ROP]],"BELOW-ROP",IF(Sim[[#This Row],[Days of supply]]>ExcessDays,IF(Sim[[#This Row],[Sept units]]>=MinVolume,"EXCESS","SLOW-MOVING"),"OK"))) -> SLOW-MOVING | U15: =IF(Sim[[#This Row],[Flag]]="No recent demand",Sim[[#This Row],[Ending on-hand]]*Sim[[#This Row],[Unit price]],IF(OR(Sim[[#This Row],[Flag]]="EXCESS",Sim[[#This Row],[Flag]]="SLOW-MOVING"),(Sim[[#This Row],[Ending on-hand]]-ExcessDays*Sim[[#This Row],[Sept daily rate]])*Sim[[#This Row],[Unit price]],0)) -> 5961.7182
... A103: 60 | B103: SOLE E25 Elliptical | C103: 0 | D103: 2 | E103: 0 | F103: 131 | G103: =Sim[[#This Row],[Avg daily demand]]*Sim[[#This Row],[Seed days]] -> 0 | H103: =Sim[[#This Row],[Seed on-hand]]-Sim[[#This Row],[Sept units]] -> -2 | I103: =Sim[[#This Row],[Sept units]]/30 -> 0.066666667 | J103: =IF(AND(Sim[[#This Row],[History units]]=0,Sim[[#This Row],[Sept units]]=0),"Inactive",IF(Sim[[#This Row],[History units]]=0,"New - no history",IF(Sim[[#This Row],[Sept units]]=0,"No recent demand",IF(Sim[[#This Row],[Ending on-hand]]<0,"Shortage risk","Normal")))) -> New - no history | K103: =IFERROR(Sim[[#This Row],[Ending on-hand]]/Sim[[#This Row],[Sept daily rate]],0) -> -30 | L103: =_xlfn.XLOOKUP(Sim[[#This Row],[Product ID]],Table3[Product ID],Table3[Rev class],,0) -> C | M103: 2.5 | N103: 999.98999 | O103: =IFERROR(_xlfn.STDEV.S(_xlfn.XLOOKUP(Sim[[#This Row],[Product ID]],Demand!$A$2:$A$101,Demand!$AD$2:$AG$101)),0) -> 0 | P103: =Sim[[#This Row],[SigmaMonthly]]/SQRT(30) -> 0 | Q103: =_xlfn.NORM.S.INV(_xlfn.XLOOKUP(Sim[[#This Row],[Class]],ServiceTbl[Class],ServiceTbl[Level])) -> 1.2815516 | R103: =ROUNDUP(Sim[[#This Row],[Z]]*Sim[[#This Row],[SigmaDaily]]*SQRT(Sim[[#This Row],[LT]]),0) -> 0 | S103: =ROUNDUP(Sim[[#This Row],[Avg daily demand]]*Sim[[#This Row],[LT]]+Sim[[#This Row],[SS]],0) -> 0 | T103: =IF(OR(Sim[[#This Row],[Status]]="Inactive",Sim[[#This Row],[Status]]="New - no history",Sim[[#This Row],[Status]]="No recent demand"),Sim[[#This Row],[Status]],IF(Sim[[#This Row],[Ending on-hand]]<=Sim[[#This Row],[ROP]],"BELOW-ROP",IF(Sim[[#This Row],[Days of supply]]>ExcessDays,IF(Sim[[#This Row],[Sept units]]>=MinVolume,"EXCESS","SLOW-MOVING"),"OK"))) -> New - no history | U103: =IF(Sim[[#This Row],[Flag]]="No recent demand",Sim[[#This Row],[Ending on-hand]]*Sim[[#This Row],[Unit price]],IF(OR(Sim[[#This Row],[Flag]]="EXCESS",Sim[[#This Row],[Flag]]="SLOW-MOVING"),(Sim[[#This Row],[Ending on-hand]]-ExcessDays*Sim[[#This Row],[Sept daily rate]])*Sim[[#This Row],[Unit price]],0)) -> 0

Sheet Demand
A1: Product ID | B1: 42005 | C1: Feb | D1: Mar | E1: Apr | F1: May | G1: Jun | H1: Jul | I1: Aug | J1: Sep | K1: Oct | L1: Nov | M1: Dec | N1: 42370 | O1: Feb | P1: Mar | Q1: Apr | R1: May | S1: Jun | T1: Jul | U1: Aug | V1: Sep | W1: Oct | X1: Nov | Y1: Dec | Z1: 42736 | AA1: Feb | AB1: Mar | AC1: Apr | AD1: May | AE1: Jun | AF1: Jul | AG1: Aug | AH1: Sep
A2: 19 | B2: 0 | C2: 0 | D2: 0 | E2: 0 | F2: 0 | G2: 0 | H2: 0 | I2: 0 | J2: 0 | K2: 0 | L2: 0 | M2: 0 | N2: 0 | O2: 0 | P2: 0 | Q2: 0 | R2: 0 | S2: 0 | T2: 0 | U2: 0 | V2: 0 | W2: 0 | X2: 0 | Y2: 0 | Z2: 0 | AA2: 0 | AB2: 0 | AC2: 2 | AD2: 13 | AE2: 13 | AF2: 14 | AG2: 17 | AH2: 4
A3: 24 | B3: 0 | C3: 0 | D3: 0 | E3: 0 | F3: 0 | G3: 0 | H3: 0 | I3: 0 | J3: 0 | K3: 0 | L3: 0 | M3: 0 | N3: 0 | O3: 0 | P3: 0 | Q3: 0 | R3: 0 | S3: 0 | T3: 0 | U3: 0 | V3: 0 | W3: 0 | X3: 0 | Y3: 0 | Z3: 0 | AA3: 0 | AB3: 0 | AC3: 12 | AD3: 70 | AE3: 52 | AF3: 45 | AG3: 42 | AH3: 9
A4: 35 | B4: 0 | C4: 0 | D4: 0 | E4: 0 | F4: 0 | G4: 0 | H4: 0 | I4: 0 | J4: 0 | K4: 0 | L4: 0 | M4: 0 | N4: 0 | O4: 0 | P4: 0 | Q4: 0 | R4: 0 | S4: 0 | T4: 0 | U4: 0 | V4: 0 | W4: 0 | X4: 0 | Y4: 0 | Z4: 0 | AA4: 0 | AB4: 0 | AC4: 4 | AD4: 15 | AE4: 11 | AF4: 14 | AG4: 13 | AH4: 5
A5: 37 | B5: 18 | C5: 20 | D5: 13 | E5: 29 | F5: 25 | G5: 11 | H5: 30 | I5: 20 | J5: 31 | K5: 8 | L5: 44 | M5: 39 | N5: 19 | O5: 32 | P5: 24 | Q5: 38 | R5: 24 | S5: 19 | T5: 52 | U5: 20 | V5: 15 | W5: 27 | X5: 34 | Y5: 24 | Z5: 34 | AA5: 28 | AB5: 48 | AC5: 14 | AD5: 0 | AE5: 0 | AF5: 0 | AG5: 0 | AH5: 0
A6: 44 | B6: 50 | C6: 23 | D6: 52 | E6: 34 | F6: 30 | G6: 33 | H6: 40 | I6: 21 | J6: 39 | K6: 31 | L6: 8 | M6: 37 | N6: 19 | O6: 36 | P6: 35 | Q6: 40 | R6: 45 | S6: 11 | T6: 51 | U6: 20 | V6: 45 | W6: 33 | X6: 25 | Y6: 35 | Z6: 30 | AA6: 17 | AB6: 36 | AC6: 36 | AD6: 0 | AE6: 0 | AF6: 0 | AG6: 0 | AH6: 0
A7: 58 | B7: 0 | C7: 0 | D7: 0 | E7: 0 | F7: 0 | G7: 0 | H7: 0 | I7: 0 | J7: 0 | K7: 0 | L7: 0 | M7: 0 | N7: 0 | O7: 0 | P7: 0 | Q7: 0 | R7: 0 | S7: 0 | T7: 0 | U7: 0 | V7: 0 | W7: 0 | X7: 0 | Y7: 0 | Z7: 0 | AA7: 0 | AB7: 0 | AC7: 0 | AD7: 0 | AE7: 0 | AF7: 0 | AG7: 0 | AH7: 28
A8: 60 | B8: 0 | C8: 0 | D8: 0 | E8: 0 | F8: 0 | G8: 0 | H8: 0 | I8: 0 | J8: 0 | K8: 0 | L8: 0 | M8: 0 | N8: 0 | O8: 0 | P8: 0 | Q8: 0 | R8: 0 | S8: 0 | T8: 0 | U8: 0 | V8: 0 | W8: 0 | X8: 0 | Y8: 0 | Z8: 0 | AA8: 0 | AB8: 0 | AC8: 0 | AD8: 0 | AE8: 0 | AF8: 0 | AG8: 0 | AH8: 2
A9: 61 | B9: 0 | C9: 0 | D9: 0 | E9: 0 | F9: 0 | G9: 0 | H9: 0 | I9: 0 | J9: 0 | K9: 0 | L9: 0 | M9: 0 | N9: 0 | O9: 0 | P9: 0 | Q9: 0 | R9: 0 | S9: 0 | T9: 0 | U9: 0 | V9: 0 | W9: 0 | X9: 0 | Y9: 0 | Z9: 0 | AA9: 0 | AB9: 0 | AC9: 0 | AD9: 0 | AE9: 0 | AF9: 0 | AG9: 0 | AH9: 26
A10: 78 | B10: 0 | C10: 0 | D10: 0 | E10: 0 | F10: 0 | G10: 0 | H10: 0 | I10: 0 | J10: 0 | K10: 0 | L10: 0 | M10: 0 | N10: 0 | O10: 0 | P10: 0 | Q10: 0 | R10: 0 | S10: 0 | T10: 0 | U10: 0 | V10: 0 | W10: 0 | X10: 0 | Y10: 0 | Z10: 0 | AA10: 0 | AB10: 0 | AC10: 10 | AD10: 42 | AE10: 43 | AF10: 37 | AG10: 33 | AH10: 16
A11: 93 | B11: 31 | C11: 20 | D11: 28 | E11: 24 | F11: 48 | G11: 19 | H11: 36 | I11: 31 | J11: 19 | K11: 29 | L11: 14 | M11: 29 | N11: 18 | O11: 26 | P11: 31 | Q11: 32 | R11: 21 | S11: 34 | T11: 25 | U11: 16 | V11: 23 | W11: 23 | X11: 38 | Y11: 48 | Z11: 44 | AA11: 41 | AB11: 35 | AC11: 14 | AD11: 0 | AE11: 0 | AF11: 0 | AG11: 0 | AH11: 0
A12: 116 | B12: 44 | C12: 28 | D12: 43 | E12: 24 | F12: 20 | G12: 26 | H12: 47 | I12: 39 | J12: 38 | K12: 26 | L12: 35 | M12: 36 | N12: 26 | O12: 21 | P12: 37 | Q12: 63 | R12: 30 | S12: 35 | T12: 40 | U12: 27 | V12: 40 | W12: 21 | X12: 29 | Y12: 42 | Z12: 41 | AA12: 43 | AB12: 30 | AC12: 23 | AD12: 0 | AE12: 0 | AF12: 0 | AG12: 0 | AH12: 0
A13: 127 | B13: 0 | C13: 0 | D13: 0 | E13: 0 | F13: 0 | G13: 0 | H13: 0 | I13: 0 | J13: 0 | K13: 0 | L13: 0 | M13: 0 | N13: 0 | O13: 0 | P13: 0 | Q13: 0 | R13: 0 | S13: 0 | T13: 0 | U13: 0 | V13: 0 | W13: 0 | X13: 0 | Y13: 0 | Z13: 0 | AA13: 0 | AB13: 0 | AC13: 0 | AD13: 0 | AE13: 0 | AF13: 0 | AG13: 0 | AH13: 25
... A101: 1073 | B101: 453 | C101: 407 | D101: 449 | E101: 468 | F101: 472 | G101: 444 | H101: 458 | I101: 461 | J101: 410 | K101: 467 | L101: 443 | M101: 478 | N101: 438 | O101: 412 | P101: 434 | Q101: 415 | R101: 495 | S101: 393 | T101: 487 | U101: 449 | V101: 456 | W101: 475 | X101: 459 | Y101: 422 | Z101: 419 | AA101: 427 | AB101: 478 | AC101: 461 | AD101: 458 | AE101: 435 | AF101: 448 | AG101: 498 | AH101: 446

Sheet Inputs
A1: ExcessDays | B1: 90 | D1: Class | E1: Level
A2: MinVolume | B2: 20 | D2: A | E2: 0.98
A3: AsOf | B3: =DATE(2017,9,30) -> 43008 | D3: B | E3: 0.95
D4: C | E4: 0.9

Sheet Summary
A1: Inventory Health Report
A2: ="Data through "&TEXT(AsOf,"d mmm yyyy")&" · 100 products · On-hand stock simulated" -> Data through 30 Sep 2017 · 100 products · On-hand stock simulated
A3: =COUNTIF(Sim[Flag],"BELOW-ROP")&" products need reordering, including "&COUNTIFS(Sim[Flag],"BELOW-ROP",Sim[Class],"A")&" of the 9 A items. "&TEXT(D5,"$#,##0")&" ("&TEXT(F5,"0%")&" of inventory value) sits in slow or unsold stock. If supplier lead time were 30 days, "&I23&" of 40 active products would need reordering." -> 11 products need reordering, including 5 of the 9 A items. $131,025 (18% of inventory value) sits in slow or unsold stock. If supplier lead time were 30 days, 21 of 40 active products would need reordering.
